<?xml version="1.0" encoding="utf-8"?>
<!-- This URDF was automatically created by SolidWorks to URDF Exporter! Originally created by Stephen Brawner (brawner@gmail.com) 
     Commit Version: 1.6.0-4-g7f85cfe  Build Version: 1.6.7995.38578
     For more information, please see http://wiki.ros.org/sw_urdf_exporter -->
<robot
  name="ArmProjectCts">
  <link
    name="arm_Link">
    <inertial>
      <origin
        xyz="0.0774467389010605 -0.0991297507644123 0.00690900212781973"
        rpy="0 0 0" />
      <mass
        value="0.232294593893707" />
      <inertia
        ixx="0.000284763775202596"
        ixy="5.76143636877517E-07"
        ixz="8.13848254440404E-08"
        iyy="0.000281741093315608"
        iyz="-8.14675787240042E-08"
        izz="0.00056118833146299" />
    </inertial>
    <visual>
      <origin
        xyz="0 0 0"
        rpy="0 0 0" />
      <geometry>
        <mesh
          filename="package://arm_description/meshes/arm_Link.STL" />
      </geometry>
      <material
        name="">
        <color
          rgba="0.250980392156863 0.250980392156863 0.250980392156863 1" />
      </material>
    </visual>
    <collision>
      <origin
        xyz="0 0 0"
        rpy="0 0 0" />
      <geometry>
        <mesh
          filename="package://arm_description/meshes/arm_Link.STL" />
      </geometry>
    </collision>
  </link>
  <link
    name="j1_Link">
    <inertial>
      <origin
        xyz="-0.00719467239022037 0.0669939976973893 0.00516422430945274"
        rpy="0 0 0" />
      <mass
        value="1.13778569832606" />
      <inertia
        ixx="0.00213539398935997"
        ixy="4.6913818851202E-05"
        ixz="3.27183343619397E-05"
        iyy="0.00208311881275953"
        iyz="-3.29509590297081E-05"
        izz="0.00215553946331751" />
    </inertial>
    <visual>
      <origin
        xyz="0 0 0"
        rpy="0 0 0" />
      <geometry>
        <mesh
          filename="package://arm_description/meshes/j1_Link.STL" />
      </geometry>
      <material
        name="">
        <color
          rgba="0.792156862745098 0.819607843137255 0.933333333333333 1" />
      </material>
    </visual>
    <collision>
      <origin
        xyz="0 0 0"
        rpy="0 0 0" />
      <geometry>
        <mesh
          filename="package://arm_description/meshes/j1_Link.STL" />
      </geometry>
    </collision>
  </link>
  <joint
    name="j1"
    type="continuous">
    <origin
      xyz="0.0774999999999998 -0.0775 0.0388999999999997"
      rpy="1.5707963267949 0 2.51744046366525" />
    <parent
      link="arm_Link" />
    <child
      link="j1_Link" />
    <axis
      xyz="0 1 0" />
  </joint>
  <link
    name="j2_Link">
    <inertial>
      <origin
        xyz="7.37454684970884E-07 -0.212502487457448 0.0680174435124814"
        rpy="0 0 0" />
      <mass
        value="2.706624786604" />
      <inertia
        ixx="0.00980555664449831"
        ixy="1.63201995488843E-06"
        ixz="1.39358759235722E-07"
        iyy="0.00504716577291593"
        iyz="3.65307715636619E-10"
        izz="0.00961310385534479" />
    </inertial>
    <visual>
      <origin
        xyz="0 0 0"
        rpy="0 0 0" />
      <geometry>
        <mesh
          filename="package://arm_description/meshes/j2_Link.STL" />
      </geometry>
      <material
        name="">
        <color
          rgba="0.792156862745098 0.819607843137255 0.933333333333333 1" />
      </material>
    </visual>
    <collision>
      <origin
        xyz="0 0 0"
        rpy="0 0 0" />
      <geometry>
        <mesh
          filename="package://arm_description/meshes/j2_Link.STL" />
      </geometry>
    </collision>
  </link>
  <joint
    name="j2"
    type="continuous">
    <origin
      xyz="-0.0491744080889805 0.0734000000000008 0.0354152169144622"
      rpy="0 0.946644136870351 3.14159265358979" />
    <parent
      link="j1_Link" />
    <child
      link="j2_Link" />
    <axis
      xyz="0 0 1" />
  </joint>
  <link
    name="j3_Link">
    <inertial>
      <origin
        xyz="4.11768821524661E-06 0.136177235047512 0.0441508655223075"
        rpy="0 0 0" />
      <mass
        value="1.64557213465188" />
      <inertia
        ixx="0.00618748643733677"
        ixy="7.88299735474947E-07"
        ixz="-3.06529566536074E-07"
        iyy="0.00216040501406518"
        iyz="2.39272845967853E-05"
        izz="0.00663809869457107" />
    </inertial>
    <visual>
      <origin
        xyz="0 0 0"
        rpy="0 0 0" />
      <geometry>
        <mesh
          filename="package://arm_description/meshes/j3_Link.STL" />
      </geometry>
      <material
        name="">
        <color
          rgba="0.792156862745098 0.819607843137255 0.933333333333333 1" />
      </material>
    </visual>
    <collision>
      <origin
        xyz="0 0 0"
        rpy="0 0 0" />
      <geometry>
        <mesh
          filename="package://arm_description/meshes/j3_Link.STL" />
      </geometry>
    </collision>
  </link>
  <joint
    name="j3"
    type="continuous">
    <origin
      xyz="0 -0.425 0"
      rpy="3.14159265358979 0 0" />
    <parent
      link="j2_Link" />
    <child
      link="j3_Link" />
    <axis
      xyz="0 0 1" />
  </joint>
  <link
    name="j4_Link">
    <inertial>
      <origin
        xyz="2.65905320264992E-05 -0.000338911001806053 0.0370989318213302"
        rpy="0 0 0" />
      <mass
        value="0.324727718002135" />
      <inertia
        ixx="0.000252393198905222"
        ixy="-1.13897192397996E-07"
        ixz="-1.06266705917643E-07"
        iyy="0.000266500312719547"
        iyz="4.95603027934183E-07"
        izz="0.0002414675974941" />
    </inertial>
    <visual>
      <origin
        xyz="0 0 0"
        rpy="0 0 0" />
      <geometry>
        <mesh
          filename="package://arm_description/meshes/j4_Link.STL" />
      </geometry>
      <material
        name="">
        <color
          rgba="0.792156862745098 0.819607843137255 0.933333333333333 1" />
      </material>
    </visual>
    <collision>
      <origin
        xyz="0 0 0"
        rpy="0 0 0" />
      <geometry>
        <mesh
          filename="package://arm_description/meshes/j4_Link.STL" />
      </geometry>
    </collision>
  </link>
  <joint
    name="j4"
    type="continuous">
    <origin
      xyz="0 0.401 0"
      rpy="3.14159263868863 0 0" />
    <parent
      link="j3_Link" />
    <child
      link="j4_Link" />
    <axis
      xyz="0 0 1" />
  </joint>
  <link
    name="j5_Link">
    <inertial>
      <origin
        xyz="-2.80611665418734E-05 -0.0446665067516046 -0.00028846278241848"
        rpy="0 0 0" />
      <mass
        value="0.307352171858084" />
      <inertia
        ixx="0.000240942908540402"
        ixy="-1.06584815003141E-07"
        ixz="-1.11953760926973E-07"
        iyy="0.000226353024923394"
        iyz="-2.05710584879931E-07"
        izz="0.000260637787894178" />
    </inertial>
    <visual>
      <origin
        xyz="0 0 0"
        rpy="0 0 0" />
      <geometry>
        <mesh
          filename="package://arm_description/meshes/j5_Link.STL" />
      </geometry>
      <material
        name="">
        <color
          rgba="0.792156862745098 0.819607843137255 0.933333333333333 1" />
      </material>
    </visual>
    <collision>
      <origin
        xyz="0 0 0"
        rpy="0 0 0" />
      <geometry>
        <mesh
          filename="package://arm_description/meshes/j5_Link.STL" />
      </geometry>
    </collision>
  </link>
  <joint
    name="j5"
    type="continuous">
    <origin
      xyz="0 -0.0374999756318092 0.0423999994412073"
      rpy="0 0 0" />
    <parent
      link="j4_Link" />
    <child
      link="j5_Link" />
    <axis
      xyz="0 -1 0" />
  </joint>
  <link
    name="j6_Link">
    <inertial>
      <origin
        xyz="-0.000337775360231829 0.000125548461417394 -0.0168048529947492"
        rpy="0 0 0" />
      <mass
        value="0.104910783608116" />
      <inertia
        ixx="4.37467245976093E-05"
        ixy="7.10729413749577E-09"
        ixz="1.28736608812063E-07"
        iyy="4.38269357529175E-05"
        iyz="-1.5581629539834E-08"
        izz="7.42996195485146E-05" />
    </inertial>
    <visual>
      <origin
        xyz="0 0 0"
        rpy="0 0 0" />
      <geometry>
        <mesh
          filename="package://arm_description/meshes/j6_Link.STL" />
      </geometry>
      <material
        name="">
        <color
          rgba="0.792156862745098 0.819607843137255 0.933333333333333 1" />
      </material>
    </visual>
    <collision>
      <origin
        xyz="0 0 0"
        rpy="0 0 0" />
      <geometry>
        <mesh
          filename="package://arm_description/meshes/j6_Link.STL" />
      </geometry>
    </collision>
  </link>
  <joint
    name="j6"
    type="continuous">
    <origin
      xyz="0 -0.0485 0.0375"
      rpy="3.1416 0 -1.5708" />
    <parent
      link="j5_Link" />
    <child
      link="j6_Link" />
    <axis
      xyz="0 0 -1" />
  </joint>
  <link
    name="camera_Link">
    <inertial>
      <origin
        xyz="0.026783320529774 0.00170482151528056 -0.00450738744405443"
        rpy="0 0 0" />
      <mass
        value="0.00120400775794929" />
      <inertia
        ixx="1.08995892811636E-08"
        ixy="5.53858781662745E-09"
        ixz="-1.47501006999919E-10"
        iyy="3.35070792414804E-07"
        iyz="-9.82687910821679E-12"
        izz="3.30027337385834E-07" />
    </inertial>
    <visual>
      <origin
        xyz="0 0 0"
        rpy="0 0 0" />
      <geometry>
        <mesh
          filename="package://arm_description/meshes/camera_Link.STL" />
      </geometry>
      <material
        name="">
        <color
          rgba="0.298039215686275 0.298039215686275 0.298039215686275 1" />
      </material>
    </visual>
    <collision>
      <origin
        xyz="0 0 0"
        rpy="0 0 0" />
      <geometry>
        <mesh
          filename="package://arm_description/meshes/camera_Link.STL" />
      </geometry>
    </collision>
  </link>
  <joint
    name="camera"
    type="fixed">
    <origin
      xyz="0.073713 -0.0295 -0.0145"
      rpy="-1.5708 0 1.5708" />
    <parent
      link="j6_Link" />
    <child
      link="camera_Link" />
    <axis
      xyz="0 0 0" />
  </joint>
</robot>